#VRML_SIM R2023b utf8

EXTERNPROTO "https://raw.githubusercontent.com/cyberbotics/webots/R2023b/projects/objects/backgrounds/protos/TexturedBackground.proto"
EXTERNPROTO "https://raw.githubusercontent.com/cyberbotics/webots/R2023b/projects/objects/backgrounds/protos/TexturedBackgroundLight.proto"
EXTERNPROTO "https://raw.githubusercontent.com/cyberbotics/webots/R2023b/projects/objects/floors/protos/CircleArena.proto"
EXTERNPROTO "https://raw.githubusercontent.com/cyberbotics/webots/R2023b/projects/appearances/protos/Plastic.proto"

WorldInfo {
  basicTimeStep 16
  contactProperties [
    DEF roda_boba_material ContactProperties {
      material2 "roda_boba_material"
      coulombFriction [
        0
      ]
    }
  ]
}
Viewpoint {
  orientation -0.577335110446447 -0.5773335784379232 0.5773821173658318 4.188765168384339
  position -1.1544458679772134 -0.13719952283399506 3.110410176816712
}
TexturedBackground {
}
TexturedBackgroundLight {
}
Robot {
  translation -1 0 0.036
  rotation 0 0 1 -1.5707
  children [
    Gyro {
      translation 0.02 -0.022 0.033
    }
    DistanceSensor {
      translation -0.067 0.0003 0.0012
      rotation 0 0 1 3.141592
      name "distance_sensor2"
      lookupTable [
        0 0 0
        0.3 3000 0.01
      ]
      type "sonar"
    }
    DistanceSensor {
      translation -0.022 -0.05 0
      rotation 0 0 1 -1.5707953071795862
      name "distance_sensor1"
      lookupTable [
        0 0 0
        0.3 3000 0.01
      ]
      type "sonar"
    }
    DistanceSensor {
      translation -0.022 0.05 0
      rotation 0 0 1 1.5707996938995747
      name "distance_sensor3"
      lookupTable [
        0 0 0
        0.3 3000 0.01
      ]
      type "sonar"
    }
    Group {
      children [
        Solid {
          translation -0.06 0 0
          children [
            Pose {
              translation 0.048 -0.013 -0.0133
              rotation 0.5773489358556708 0.5773509358554485 0.5773509358554485 2.0944
              children [
                DEF sensor CadShape {
                  url [
                    "../Parts/Montagem Final 21.10 v7 sensor.obj"
                  ]
                }
              ]
            }
          ]
          name "sensor2"
          boundingObject DEF sensorBO Box {
            size 0.013 0.048 0.031
          }
          physics DEF physics_Sensor Physics {
          }
        }
        Solid {
          translation -0.022 -0.044 0
          rotation 0 0 1 1.5708
          children [
            Pose {
              translation 0.048 -0.013 -0.0133
              rotation 0.5773489358556708 0.5773509358554485 0.5773509358554485 2.0944
              children [
                USE sensor
              ]
            }
          ]
          name "sensor2"
          boundingObject USE sensorBO
          physics USE physics_Sensor
        }
        Solid {
          translation -0.022 0.044 0
          rotation 0 0 1 -1.5707953071795862
          children [
            Pose {
              translation 0.048 -0.013 -0.0133
              rotation 0.5773489358556708 0.5773509358554485 0.5773509358554485 2.0944
              children [
                USE sensor
              ]
            }
          ]
          name "sensor3"
          boundingObject USE sensorBO
          physics USE physics_Sensor
        }
        BallJoint {
          jointParameters BallJointParameters {
            position 1.1736605513171827
            anchor -0.027870997249746867 0.0001610450457207897 -0.030606030849649118
          }
          jointParameters2 JointParameters {
            position -2.193628787780284
            axis 1 0 0
          }
          jointParameters3 JointParameters {
            position -26.02914266316667
          }
          endPoint Solid {
            translation -0.027870997249746867 0.0001610450457207897 -0.030606030849649118
            rotation 0.5534669528473949 -0.5629041551959418 -0.6138511579926867 2.8828095881745437
            boundingObject Sphere {
              radius 0.0055
            }
            physics Physics {
            }
          }
        }
        HingeJoint {
          jointParameters HingeJointParameters {
            position 4.019736650879649
            axis 0 -1 0
            anchor 0.0285 0.04044 -0.0181
          }
          device [
            RotationalMotor {
              name "motor_1"
            }
          ]
          endPoint Solid {
            translation 0.0285 0.04044 -0.0181
            rotation -0.3151668193730296 -0.6710687623564011 0.6710712273341305 3.7522157039677
            children [
              Pose {
                translation -0.0405 0.0046 0.0535
                rotation 0 1 0 1.57
                children [
                  DEF wheel CadShape {
                    url [
                      "../Parts/Montagem Final 21.10 v6 wheel.obj"
                    ]
                  }
                ]
              }
            ]
            name "motor1"
            boundingObject DEF wheelBO Shape {
              appearance PBRAppearance {
                baseColor 0.2 0.2 1
                roughness 1
                metalness 0
              }
              geometry Cylinder {
                height 0.006
                radius 0.017
              }
            }
            physics DEF wheel_physics2 Physics {
            }
          }
        }
        HingeJoint {
          jointParameters HingeJointParameters {
            position 4.019736639613765
            axis 0 -1 0
            anchor 0.0285 -0.0399 -0.0181
          }
          device [
            RotationalMotor {
              name "motor_2"
            }
          ]
          endPoint Solid {
            translation 0.0285 -0.0399 -0.0181
            rotation -0.31516614916392904 -0.6710704943440768 0.6710698101106742 3.7522171754272193
            children [
              Pose {
                translation 0.0404 0.0045 -0.0534
                rotation 0 -1 0 1.57
                children [
                  USE wheel
                ]
              }
            ]
            name "motor2"
            boundingObject USE wheelBO
            physics USE wheel_physics2
          }
        }
        Solid {
          children [
            Pose {
              translation -0.012 -0.013 -0.0135
              rotation 0.5773509358554485 0.5773489358556708 0.5773509358554485 2.0944
              children [
                CadShape {
                  url [
                    "../Parts/Montagem Final 21.10 v10 body.obj"
                  ]
                }
              ]
            }
          ]
          name "body"
          boundingObject DEF shape_body Shape {
            appearance PBRAppearance {
              roughness 1
              metalness 0
            }
            geometry Box {
              size 0.0945 0.07 0.05
            }
          }
          physics Physics {
          }
        }
      ]
    }
  ]
  boundingObject USE shape_body
  physics Physics {
  }
  controller "maze_solution_algorithm"
}
Solid {
  rotation 1 0 0 1.57
  children [
    DEF maze Shape {
      appearance Plastic {
        colorOverride 0.854902 0.854902 0.854902
        type "padded"
        textureTransform TextureTransform {
          center 0.366 0.113
          scale 1.679 1.679
        }
      }
      geometry DEF mazeGeo Mesh {
        url [
          "../Parts/maze1.obj"
        ]
      }
    }
  ]
  name "maze"
  boundingObject USE maze
}
CircleArena {
  translation 2.1 0 0
}
