#VRML_SIM R2023b utf8

EXTERNPROTO "https://raw.githubusercontent.com/cyberbotics/webots/R2023b/projects/objects/backgrounds/protos/TexturedBackground.proto"
EXTERNPROTO "https://raw.githubusercontent.com/cyberbotics/webots/R2023b/projects/objects/backgrounds/protos/TexturedBackgroundLight.proto"
EXTERNPROTO "https://raw.githubusercontent.com/cyberbotics/webots/R2023b/projects/objects/floors/protos/CircleArena.proto"
EXTERNPROTO "https://raw.githubusercontent.com/cyberbotics/webots/R2023b/projects/appearances/protos/Plastic.proto"

WorldInfo {
  basicTimeStep 16
  contactProperties [
    DEF roda_boba_material ContactProperties {
      material2 "roda_boba_material"
      coulombFriction [
        0
      ]
    }
  ]
}
Viewpoint {
  orientation 0.5673044739932817 0.567812292206006 -0.5964518711572352 2.065263980516842
  position -0.26451027550956524 0.4995658852729387 0.6649023605700131
}
TexturedBackground {
}
TexturedBackgroundLight {
}
Robot {
  translation -0.25 0.5 0.0356099
  rotation 0 0 1 1.5707
  children [
    Gyro {
      translation 0.02 -0.022 0.033
    }
    DistanceSensor {
      translation -0.067 0.0003 0.0012
      rotation 0 0 1 3.141592
      name "distance_sensor2"
      lookupTable [
        0 0 0
        0.3 3000 0.01
      ]
      type "sonar"
    }
    DistanceSensor {
      translation -0.022 -0.05 0
      rotation 0 0 1 -1.5707953071795862
      name "distance_sensor1"
      lookupTable [
        0 0 0
        0.3 3000 0.01
      ]
      type "sonar"
    }
    DistanceSensor {
      translation -0.022 0.05 0
      rotation 0 0 1 1.5707996938995747
      name "distance_sensor3"
      lookupTable [
        0 0 0
        0.3 3000 0.01
      ]
      type "sonar"
    }
    Group {
      children [
        Solid {
          translation -0.06 0 0
          children [
            Pose {
              translation 0.048 -0.013 -0.0133
              rotation 0.5773489358556708 0.5773509358554485 0.5773509358554485 2.0944
              children [
                DEF sensor CadShape {
                  url [
                    "../Parts/Montagem Final 21.10 v7 sensor.obj"
                  ]
                }
              ]
            }
          ]
          name "sensor2"
          boundingObject DEF sensorBO Box {
            size 0.013 0.048 0.031
          }
          physics DEF physics_Sensor Physics {
          }
        }
        Solid {
          translation -0.022 -0.044 0
          rotation 0 0 1 1.5708
          children [
            Pose {
              translation 0.048 -0.013 -0.0133
              rotation 0.5773489358556708 0.5773509358554485 0.5773509358554485 2.0944
              children [
                USE sensor
              ]
            }
          ]
          name "sensor2"
          boundingObject USE sensorBO
          physics USE physics_Sensor
        }
        Solid {
          translation -0.022 0.044 0
          rotation 0 0 1 -1.5707953071795862
          children [
            Pose {
              translation 0.048 -0.013 -0.0133
              rotation 0.5773489358556708 0.5773509358554485 0.5773509358554485 2.0944
              children [
                USE sensor
              ]
            }
          ]
          name "sensor3"
          boundingObject USE sensorBO
          physics USE physics_Sensor
        }
        BallJoint {
          jointParameters BallJointParameters {
            position 13.757583002164036
            anchor -0.027870997249746867 0.0001610450457207897 -0.030606030849649118
          }
          jointParameters2 JointParameters {
            position -2.1403502393353278
            axis 1 0 0
          }
          jointParameters3 JointParameters {
            position -0.5800088470559552
          }
          endPoint Solid {
            translation -0.027870997249746867 0.0001610450457207897 -0.030606030849649118
            rotation 0.479713010376813 -0.6375317226792354 -0.6028505040661923 2.656872226641708
            boundingObject Sphere {
              radius 0.0055
            }
            physics Physics {
            }
          }
        }
        HingeJoint {
          jointParameters HingeJointParameters {
            position 11.658478014229786
            axis 0 -1 0
            anchor 0.0285 0.04044 -0.0181
          }
          device [
            RotationalMotor {
              name "motor_1"
            }
          ]
          endPoint Solid {
            translation 0.0285 0.04044 -0.0181
            rotation 0.8230654516235278 0.40159810601068396 -0.40159958116560557 1.7643005334073503
            children [
              Pose {
                translation -0.0405 0.0046 0.0535
                rotation 0 1 0 1.57
                children [
                  DEF wheel CadShape {
                    url [
                      "../Parts/Montagem Final 21.10 v6 wheel.obj"
                    ]
                  }
                ]
              }
            ]
            name "motor1"
            boundingObject DEF wheelBO Shape {
              appearance PBRAppearance {
                baseColor 0.2 0.2 1
                roughness 1
                metalness 0
              }
              geometry Cylinder {
                height 0.006
                radius 0.017
              }
            }
            physics DEF wheel_physics2 Physics {
            }
          }
        }
        HingeJoint {
          jointParameters HingeJointParameters {
            position 3.8023040531583696
            axis 0 -1 0
            anchor 0.0285 -0.0399 -0.0181
          }
          device [
            RotationalMotor {
              name "motor_2"
            }
          ]
          endPoint Solid {
            translation 0.0285 -0.0399 -0.0181
            rotation -0.23565358558911562 -0.6871929680200473 0.6871922673479319 3.6044556098487406
            children [
              Pose {
                translation 0.0404 0.0045 -0.0534
                rotation 0 -1 0 1.57
                children [
                  USE wheel
                ]
              }
            ]
            name "motor2"
            boundingObject USE wheelBO
            physics USE wheel_physics2
          }
        }
        Solid {
          children [
            Pose {
              translation -0.012 -0.013 -0.0135
              rotation 0.5773509358554485 0.5773489358556708 0.5773509358554485 2.0944
              children [
                CadShape {
                  url [
                    "../Parts/Montagem Final 21.10 v10 body.obj"
                  ]
                }
              ]
            }
          ]
          name "body"
          boundingObject DEF shape_body Shape {
            appearance PBRAppearance {
              roughness 1
              metalness 0
            }
            geometry Box {
              size 0.0945 0.07 0.05
            }
          }
          physics Physics {
          }
        }
      ]
    }
  ]
  boundingObject USE shape_body
  physics Physics {
  }
  controller "maze_solution_algorithm"
}
Solid {
  rotation 1 0 0 1.57
  children [
    DEF maze Shape {
      appearance Plastic {
        colorOverride 0.854902 0.854902 0.854902
        type "padded"
        textureTransform TextureTransform {
          center 0.366 0.113
          scale 1.679 1.679
        }
      }
      geometry DEF mazeGeo Mesh {
        url [
          "../Parts/maze1.obj"
        ]
      }
    }
  ]
  name "maze"
  boundingObject USE maze
}
CircleArena {
  translation 2.1 0 0
}
